<?xml version='1.0' encoding='utf-8'?>
<robot name="fr3_robot">
  <!-- Base link (root) -->
  <link name="base_link">
    <inertial>
      <origin xyz="0 0 0" rpy="0 0 0" />
      <mass value="0.001" />
      <inertia ixx="0.001" iyy="0.001" izz="0.001" ixy="0" ixz="0" iyz="0" />
    </inertial>
  </link>
  
  <!-- Robot base link -->
  <link name="fr3_panda_link0">
    <inertial>
      <origin xyz="-0.041018 -0.00014 0.049974" rpy="0 0 0" />
      <mass value="0.629769" />
      <inertia ixx="0.00315" iyy="0.00388" izz="0.004285" ixy="8.2904e-07" ixz="0.00015" iyz="8.2299e-06" />
    </inertial>
    <visual>
      <origin xyz="0 0 0" rpy="0 0 0" />
      <geometry>
        <mesh filename="package://role_ros2/robot_ik/franka/mesh/link0.obj" />
      </geometry>
      <material name="panda_material">
        <color rgba="0.8 0.8 0.8 1" />
      </material>
    </visual>
    <collision>
      <origin xyz="0 0 0" rpy="0 0 0" />
      <geometry>
        <mesh filename="package://role_ros2/robot_ik/franka/mesh/link0.obj" />
      </geometry>
    </collision>
  </link>
  <joint name="fr3_base_joint" type="fixed">
    <parent link="base_link" />
    <child link="fr3_panda_link0" />
    <origin rpy="0 0 0" xyz="0.0 0.0 0.0" />
  </joint>
  
  <!-- Joint 1 -->
  <link name="fr3_panda_link1">
    <inertial>
      <origin xyz="0.003875 0.002081 -0.04762" rpy="0 0 0" />
      <mass value="4.970684" />
      <inertia ixx="0.70337" iyy="0.70661" izz="0.009117" ixy="-0.000139" ixz="0.006772" iyz="0.019169" />
    </inertial>
    <visual>
      <origin xyz="0 0 0" rpy="0 0 0" />
      <geometry>
        <mesh filename="package://role_ros2/robot_ik/franka/mesh/link1.obj" />
      </geometry>
      <material name="panda_material">
        <color rgba="0.8 0.8 0.8 1" />
      </material>
    </visual>
    <collision>
      <origin xyz="0 0 0" rpy="0 0 0" />
      <geometry>
        <mesh filename="package://role_ros2/robot_ik/franka/mesh/link1.obj" />
      </geometry>
    </collision>
  </link>
  <joint name="fr3_panda_joint1" type="revolute">
    <parent link="fr3_panda_link0" />
    <child link="fr3_panda_link1" />
    <origin rpy="0 0 0" xyz="0.0 0.0 0.333" />
    <axis xyz="0.0 0.0 1.0" />
    <limit lower="-2.7437" upper="2.7437" effort="87" velocity="2.175" />
  </joint>
  
  <!-- Joint 2 -->
  <link name="fr3_panda_link2">
    <inertial>
      <origin xyz="-0.003141 -0.02872 0.003495" rpy="0 0 0" />
      <mass value="0.646926" />
      <inertia ixx="0.007962" iyy="0.02811" izz="0.025995" ixy="-0.003925" ixz="0.010254" iyz="0.000704" />
    </inertial>
    <visual>
      <origin xyz="0 0 0" rpy="0 0 0" />
      <geometry>
        <mesh filename="package://role_ros2/robot_ik/franka/mesh/link2.obj" />
      </geometry>
      <material name="panda_material">
        <color rgba="0.8 0.8 0.8 1" />
      </material>
    </visual>
    <collision>
      <origin xyz="0 0 0" rpy="0 0 0" />
      <geometry>
        <mesh filename="package://role_ros2/robot_ik/franka/mesh/link2.obj" />
      </geometry>
    </collision>
  </link>
  <joint name="fr3_panda_joint2" type="revolute">
    <parent link="fr3_panda_link1" />
    <child link="fr3_panda_link2" />
    <origin rpy="-1.5707969456925137 0.0 0.0" xyz="0.0 0.0 0.0" />
    <axis xyz="0.0 0.0 1.0" />
    <limit lower="-1.7837" upper="1.7837" effort="87" velocity="2.175" />
  </joint>
  
  <!-- Joint 3 -->
  <link name="fr3_panda_link3">
    <inertial>
      <origin xyz="0.027518 0.039252 -0.066502" rpy="0 0 0" />
      <mass value="3.228604" />
      <inertia ixx="0.037242" iyy="0.036155" izz="0.01083" ixy="-0.004761" ixz="-0.011396" iyz="-0.012805" />
    </inertial>
    <visual>
      <origin xyz="0 0 0" rpy="0 0 0" />
      <geometry>
        <mesh filename="package://role_ros2/robot_ik/franka/mesh/link3.obj" />
      </geometry>
      <material name="panda_material">
        <color rgba="0.8 0.8 0.8 1" />
      </material>
    </visual>
    <collision>
      <origin xyz="0 0 0" rpy="0 0 0" />
      <geometry>
        <mesh filename="package://role_ros2/robot_ik/franka/mesh/link3.obj" />
      </geometry>
    </collision>
  </link>
  <joint name="fr3_panda_joint3" type="revolute">
    <parent link="fr3_panda_link2" />
    <child link="fr3_panda_link3" />
    <origin rpy="1.5707969456925137 0.0 0.0" xyz="0.0 -0.316 0.0" />
    <axis xyz="0.0 0.0 1.0" />
    <limit lower="-2.9007" upper="2.9007" effort="87" velocity="2.175" />
  </joint>
  
  <!-- Joint 4 -->
  <link name="fr3_panda_link4">
    <inertial>
      <origin xyz="-0.05317 0.104419 0.027454" rpy="0 0 0" />
      <mass value="3.587895" />
      <inertia ixx="0.025853" iyy="0.019552" izz="0.028323" ixy="0.007796" ixz="-0.001332" iyz="0.008641" />
    </inertial>
    <visual>
      <origin xyz="0 0 0" rpy="0 0 0" />
      <geometry>
        <mesh filename="package://role_ros2/robot_ik/franka/mesh/link4.obj" />
      </geometry>
      <material name="panda_material">
        <color rgba="0.8 0.8 0.8 1" />
      </material>
    </visual>
    <collision>
      <origin xyz="0 0 0" rpy="0 0 0" />
      <geometry>
        <mesh filename="package://role_ros2/robot_ik/franka/mesh/link4.obj" />
      </geometry>
    </collision>
  </link>
  <joint name="fr3_panda_joint4" type="revolute">
    <parent link="fr3_panda_link3" />
    <child link="fr3_panda_link4" />
    <origin rpy="1.5707969456925137 0.0 0.0" xyz="0.0825 0.0 0.0" />
    <axis xyz="0.0 0.0 1.0" />
    <limit lower="-3.0421" upper="-0.1518" effort="87" velocity="2.175" />
  </joint>
  
  <!-- Joint 5 -->
  <link name="fr3_panda_link5">
    <inertial>
      <origin xyz="0.011953 0.041065 -0.038437" rpy="0 0 0" />
      <mass value="1.225946" />
      <inertia ixx="0.035549" iyy="0.029474" izz="0.008627" ixy="-0.002117" ixz="-0.004037" iyz="0.000229" />
    </inertial>
    <visual>
      <origin xyz="0 0 0" rpy="0 0 0" />
      <geometry>
        <mesh filename="package://role_ros2/robot_ik/franka/mesh/link5.obj" />
      </geometry>
      <material name="panda_material">
        <color rgba="0.8 0.8 0.8 1" />
      </material>
    </visual>
    <collision>
      <origin xyz="0 0 0" rpy="0 0 0" />
      <geometry>
        <mesh filename="package://role_ros2/robot_ik/franka/mesh/link5.obj" />
      </geometry>
    </collision>
  </link>
  <joint name="fr3_panda_joint5" type="revolute">
    <parent link="fr3_panda_link4" />
    <child link="fr3_panda_link5" />
    <origin rpy="-1.5707969456925137 0.0 0.0" xyz="-0.0825 0.384 0.0" />
    <axis xyz="0.0 0.0 1.0" />
    <limit lower="-2.8065" upper="2.8065" effort="87" velocity="2.175" />
  </joint>
  
  <!-- Joint 6 -->
  <link name="fr3_panda_link6">
    <inertial>
      <origin xyz="0.060149 -0.014117 -0.010517" rpy="0 0 0" />
      <mass value="1.666555" />
      <inertia ixx="0.001964" iyy="0.004354" izz="0.005433" ixy="0.000109" ixz="-0.001158" iyz="0.000341" />
    </inertial>
    <visual>
      <origin xyz="0 0 0" rpy="0 0 0" />
      <geometry>
        <mesh filename="package://role_ros2/robot_ik/franka/mesh/link6.obj" />
      </geometry>
      <material name="panda_material">
        <color rgba="0.8 0.8 0.8 1" />
      </material>
    </visual>
    <collision>
      <origin xyz="0 0 0" rpy="0 0 0" />
      <geometry>
        <mesh filename="package://role_ros2/robot_ik/franka/mesh/link6.obj" />
      </geometry>
    </collision>
  </link>
  <joint name="fr3_panda_joint6" type="revolute">
    <parent link="fr3_panda_link5" />
    <child link="fr3_panda_link6" />
    <origin rpy="1.5707969456925137 0.0 0.0" xyz="0.0 0.0 0.0" />
    <axis xyz="0.0 0.0 1.0" />
    <limit lower="0.5445" upper="4.5169" effort="87" velocity="2.175" />
  </joint>
  
  <!-- Joint 7 -->
  <link name="fr3_panda_link7">
    <inertial>
      <origin xyz="0.010517 -0.004252 0.061597" rpy="0 0 0" />
      <mass value="0.735522" />
      <inertia ixx="0.012516" iyy="0.010027" izz="0.004815" ixy="-0.000428" ixz="-0.001196" iyz="-0.000741" />
    </inertial>
    <visual>
      <origin xyz="0 0 0" rpy="0 0 0" />
      <geometry>
        <mesh filename="package://role_ros2/robot_ik/franka/mesh/link7.obj" />
      </geometry>
      <material name="panda_material">
        <color rgba="0.8 0.8 0.8 1" />
      </material>
    </visual>
    <collision>
      <origin xyz="0 0 0" rpy="0 0 0" />
      <geometry>
        <mesh filename="package://role_ros2/robot_ik/franka/mesh/link7.obj" />
      </geometry>
    </collision>
  </link>
  <joint name="fr3_panda_joint7" type="revolute">
    <parent link="fr3_panda_link6" />
    <child link="fr3_panda_link7" />
    <origin rpy="1.5707969456925137 0.0 0.0" xyz="0.088 0.0 0.0" />
    <axis xyz="0.0 0.0 1.0" />
    <limit lower="-3.0159" upper="3.0159" effort="87" velocity="2.175" />
  </joint>
  
  <!-- End-effector (hand) - directly connected to link7 -->
  <link name="fr3_panda_hand">
    <inertial>
      <origin xyz="-0.01 0.0 0.03" rpy="0 0 0" />
      <mass value="0.73" />
      <inertia ixx="0.001" iyy="0.0025" izz="0.0017" ixy="0" ixz="0" iyz="0" />
    </inertial>
    <visual>
      <origin xyz="0 0 0" rpy="0 0 0" />
      <geometry>
        <mesh filename="package://role_ros2/robot_ik/franka/mesh/hand.obj" />
      </geometry>
      <material name="panda_material">
        <color rgba="0.8 0.8 0.8 1" />
      </material>
    </visual>
    <collision>
      <origin xyz="0 0 0" rpy="0 0 0" />
      <geometry>
        <mesh filename="package://role_ros2/robot_ik/franka/mesh/hand.obj" />
      </geometry>
    </collision>
  </link>
  <joint name="fr3_panda_hand_fixed_joint" type="fixed">
    <parent link="fr3_panda_link7" />
    <child link="fr3_panda_hand" />
    <origin rpy="0.0 0.0 -0.785398163397" xyz="0.0 0.0 0.107" />
  </joint>
</robot>
